Workbook

Sheet Dhan_Signals
A1: Timestamp | B1: Signal | C1: Confidence | D1: RSI | E1: MACD | F1: Momentum | G1: Volume Ratio | H1: VIX | I1: Sentiment | J1: Writers Zone | K1: Candle Pattern | L1: Spot Price | M1: Market Strength | N1: Put Call Premium Ratio | O1: Writers Confidence | P1: ATM Strike
A2: 2025-07-31T05:17:20.919Z | B2: WAIT | C2: 0 | D2: {"rsi":"44.22","status":"Neutral"} | E2: {"macd":"0.19","signal":"0.19","histogram":"0.00","status":"Neutral"} | J2: NEUTRAL | P2: 24700
A3: 2025-07-31T05:29:32.210Z | B3: WAIT | C3: 0 | D3: {"rsi":"44.22","status":"Neutral"} | E3: {"macd":"0.19","signal":"0.19","histogram":"0.00","status":"Neutral"} | J3: NEUTRAL | P3: 24700
A4: 2025-07-31T05:30:02.529Z | B4: WAIT | C4: 0 | D4: {"rsi":"44.22","status":"Neutral"} | E4: {"macd":"0.19","signal":"0.19","histogram":"0.00","status":"Neutral"} | J4: NEUTRAL | P4: 24700
A5: 2025-07-31T05:35:02.831Z | B5: WAIT | C5: 0 | D5: {"rsi":"44.22","status":"Neutral"} | E5: {"macd":"0.19","signal":"0.19","histogram":"0.00","status":"Neutral"} | J5: NEUTRAL | P5: 24750
A6: 2025-07-31T05:40:02.690Z | B6: WAIT | C6: 0 | D6: {"rsi":"44.22","status":"Neutral"} | E6: {"macd":"0.19","signal":"0.19","histogram":"0.00","status":"Neutral"} | J6: NEUTRAL | P6: 24750
A7: 2025-07-31T05:45:02.529Z | B7: WAIT | C7: 0 | D7: {"rsi":"44.22","status":"Neutral"} | E7: {"macd":"0.19","signal":"0.19","histogram":"0.00","status":"Neutral"} | J7: NEUTRAL | P7: 24750
A8: 2025-07-31T05:50:02.609Z | B8: WAIT | C8: 0 | D8: {"rsi":"44.22","status":"Neutral"} | E8: {"macd":"0.19","signal":"0.19","histogram":"0.00","status":"Neutral"} | J8: NEUTRAL | P8: 24750
A9: 2025-07-31T05:55:02.299Z | B9: WAIT | C9: 0 | D9: {"rsi":"44.22","status":"Neutral"} | E9: {"macd":"0.19","signal":"0.19","histogram":"0.00","status":"Neutral"} | J9: NEUTRAL | P9: 24800
A10: 2025-07-31T18:01:01.161Z | B10: WAIT | C10: 0 | D10: {"rsi":"20.16","status":"Oversold"} | E10: {"macd":"-38.73","signal":"-38.73","histogram":"0.00","status":"Neutral"} | J10: NEUTRAL | P10: 24750
A11: 2025-07-31T18:01:01.161Z | B11: BUY PUT (PE) | C11: -70 | D11: {"rsi":"20.16","status":"Oversold"} | E11: {"macd":"-38.73","signal":"-38.73","histogram":"0.00","status":"Neutral"} | J11: NEUTRAL | P11: 24750
A12: 2025-07-31T18:01:01.161Z | B12: BUY PUT (PE) | C12: -70 | D12: {"rsi":"20.16","status":"Oversold"} | E12: {"macd":"-38.73","signal":"-38.73","histogram":"0.00","status":"Neutral"} | J12: NEUTRAL | P12: 24750
A13: 2025-07-31T18:01:01.161Z | B13: BUY CALL (CE) | C13: 65 | D13: {"rsi":"20.16","status":"Oversold"} | E13: {"macd":"-38.73","signal":"-38.73","histogram":"0.00","status":"Neutral"} | J13: NEUTRAL | P13: 24750
... A19: 2025-07-31T21:33:32.761Z | B19: WAIT | C19: 20 | D19: {"rsi":"20.16","status":"Oversold"} | E19: {"macd":"-38.73","signal":"-38.73","histogram":"0.00","status":"Neutral"} | J19: NEUTRAL | P19: 24750
A20: 2025-07-31T22:16:00.459Z | B20: WAIT | C20: 15 | D20: {"rsi":"20.16","status":"Oversold"} | E20: {"macd":"-38.73","signal":"-38.73","histogram":"0.00","status":"Neutral"} | H20: 11.54 | J20: NEUTRAL | P20: 24750
A21: 2025-07-31T22:16:00.459Z | B21: BUY CALL (CE) | C21: 15 | D21: {"rsi":"20.16","status":"Oversold"} | E21: {"macd":"-38.73","signal":"-38.73","histogram":"0.00","status":"Neutral"} | H21: 11.54 | J21: NEUTRAL | P21: 24750
A22: 2025-07-31T22:31:04.824Z | B22: BUY CALL (CE) | C22: 15 | D22: {"rsi":"20.16","status":"Oversold"} | E22: {"macd":"-38.73","signal":"-38.73","histogram":"0.00","status":"Neutral"} | H22: 11.54 | J22: NEUTRAL | P22: 24750
A23: 2025-07-31T22:32:13.007Z | B23: BUY CALL (CE) | C23: 15 | D23: {"rsi":"20.16","status":"Oversold"} | E23: {"macd":"-38.73","signal":"-38.73","histogram":"0.00","status":"Neutral"} | H23: 11.54 | J23: NEUTRAL | P23: 24750
A24: 2025-07-31T22:32:13.007Z | B24: BUY CALL (CE) | C24: 15 | D24: {"rsi":"20.16","status":"Oversold"} | E24: {"macd":"-38.73","signal":"-38.73","histogram":"0.00","status":"Neutral"} | H24: 11.54 | J24: NEUTRAL | L24: 24768.35 | N24: 1 | O24: 0 | P24: 24750
A25: 2025-07-31T05:09:23.744Z | B25: WAIT | C25: 0 | D25: {"rsi":"44.22","status":"Neutral"} | E25: {"macd":"0.19","signal":"0.19","histogram":"0.00","status":"Neutral"} | J25: NEUTRAL | P25: 24650
A26: 2025-07-31T22:32:13.007Z | B26: BUY CALL (CE) | C26: 15 | D26: 20.16 | E26: -38.73 | H26: 11.54 | J26: NEUTRAL | L26: 24768.35 | N26: 1 | O26: 0 | P26: 24750
A27: 2025-07-31T22:43:34.169Z | B27: BUY CALL (CE) | C27: 15 | D27: 20.16 | E27: -38.73 | H27: 11.54 | J27: NEUTRAL | L27: 24768.35 | N27: 1 | O27: 0 | P27: 24750
A28: 2025-08-01T19:46:48.809Z | B28: WAIT | C28: 5 | D28: 31.59 | E28: -25.04 | H28: 11.97 | J28: NEUTRAL | L28: 24565.35 | N28: 1 | O28: 0 | P28: 24550
A29: 2025-08-01T19:52:19.366Z | B29: WAIT | C29: 5 | D29: 31.59 | E29: -25.04 | H29: 11.97 | J29: NEUTRAL | L29: 24565.35 | N29: 1 | O29: 0 | P29: 24550
A30: 2025-08-01T19:57:06.980Z | B30: WAIT | C30: 5 | D30: 31.59 | E30: -25.04 | H30: 11.97 | J30: NEUTRAL | L30: 24565.35 | N30: 1 | O30: 0 | P30: 24550
A31: 2025-08-01T19:57:06.980Z | B31: WAIT | C31: 5 | D31: 31.59 | E31: -25.04 | H31: 11.97 | J31: NEUTRAL | L31: 24565.35 | N31: 1 | O31: 0 | P31: 24550
A32: 2025-08-01T20:37:31.500Z | B32: WAIT | C32: 5 | D32: 31.59 | E32: -25.04 | H32: 11.97 | J32: NEUTRAL | L32: 24565.35 | N32: 1 | O32: 0 | P32: 24550
A33: 2025-08-01T20:46:27.550Z | B33: WAIT | C33: 5 | D33: 31.59 | E33: -25.04 | H33: 11.97 | J33: NEUTRAL | L33: 24565.35 | N33: 1 | O33: 0 | P33: 24550
A34: 2025-08-01T20:58:51.131Z | B34: WAIT | C34: 5 | D34: 31.59 | E34: -25.04 | H34: 11.97 | J34: NEUTRAL | L34: 24565.35 | N34: 1 | O34: 0 | P34: 24550
A35: 2025-08-01T21:41:37.037Z | B35: WAIT | C35: 5 | D35: 31.59 | E35: -25.04 | H35: 11.97 | J35: NEUTRAL | L35: 24565.35 | N35: 1 | O35: 0 | P35: 24550
A36: 2025-08-01T21:59:58.866Z | B36: BUY CALL (CE) | C36: 5 | D36: 31.59 | E36: -25.04 | H36: 11.97 | J36: NEUTRAL | L36: 24565.35 | N36: 1 | O36: 0 | P36: 24550
A37: 2025-08-01T22:02:54.897Z | B37: BUY CALL (CE) | C37: 5 | D37: 31.59 | E37: -25.04 | H37: 11.97 | J37: NEUTRAL | L37: 24565.35 | N37: 1 | O37: 0 | P37: 24550
... A47: 2025-08-02T20:17:13.439Z | B47: BUY CALL (CE) | C47: 5 | D47: 31.59 | E47: -25.04 | H47: 11.97 | J47: NEUTRAL | L47: 24565.35 | N47: 1 | O47: 0 | P47: 24550
A48: 2025-08-03T04:48:14.477Z | B48: BUY CALL (CE) | C48: 30 | D48: 0 | E48: 0.00 | H48: 11.97 | J48: NEUTRAL | L48: 24565.35 | N48: 1 | O48: 0 | P48: 24550
A49: 2025-08-03T04:49:03.549Z | B49: BUY CALL (CE) | C49: 30 | D49: 0 | E49: 0.00 | H49: 11.97 | J49: NEUTRAL | L49: 24565.35 | N49: 1 | O49: 0 | P49: 24550
A50: 2025-08-03T04:49:19.922Z | B50: BUY CALL (CE) | C50: 30 | D50: 0 | E50: 0.00 | H50: 11.97 | J50: NEUTRAL | L50: 24565.35 | N50: 1 | O50: 0 | P50: 24550
A51: 2025-08-03T04:51:16.004Z | B51: BUY CALL (CE) | C51: 30 | D51: 0 | E51: 0.00 | H51: 11.97 | J51: NEUTRAL | L51: 24565.35 | N51: 1 | O51: 0 | P51: 24550
A52: 2025-08-03T04:53:03.995Z | B52: BUY CALL (CE) | C52: 30 | D52: 0 | E52: 0.00 | H52: 11.97 | J52: NEUTRAL | L52: 24565.35 | N52: 1 | O52: 0 | P52: 24550
A53: 2025-08-03T04:53:03.995Z | B53: BUY CALL (CE) | C53: 30 | D53: 0 | E53: 0.00 | H53: 11.97 | J53: NEUTRAL | L53: 24565.35 | N53: 1 | O53: 0 | P53: 24550
A54: 2025-08-03T06:36:32.753Z | B54: BUY CALL (CE) | C54: 30 | D54: 0 | E54: 0.00 | H54: 11.97 | J54: NEUTRAL | L54: 24565.35 | N54: 1 | O54: 0 | P54: 24550
...

Sheet Dhan_Active_Trades
A1: Entry Order ID | B1: SL Order ID | C1: Target Order ID | D1: Trading Symbol | E1: Security ID | F1: Entry Price | G1: Stop Loss | H1: Target | I1: Quantity | J1: Risk Reward Ratio | K1: Max Loss | L1: Max Profit | M1: Status | N1: Timestamp | O1: Exit Type | P1: Exit Price | Q1: PnL | R1: Actual Risk Reward | S1: Exit Timestamp | T1: Execution Time

Sheet Dhan_Trade_Summary
A1: Entry Order ID | B1: Timestamp | C1: Signal | D1: Confidence | E1: Trading Symbol | F1: Entry Price | G1: Stop Loss | H1: Target | I1: Quantity | J1: Risk Reward Ratio | K1: Max Loss | L1: Max Profit | M1: Writers Zone | N1: Market Strength | O1: VIX | P1: Status | Q1: Exit Price | R1: PnL | S1: Exit Type | T1: Actual Risk Reward | U1: Exit Timestamp

Sheet Dhan_Performance_Log
A1: Date | B1: Session Executions | C1: Session PnL | D1: Target Hits | E1: Stop Loss Hits | F1: Average PnL | G1: Win Rate | H1: Profit Factor | I1: Max Drawdown | J1: Last Update | K1: Total Trades | L1: Win Rate | M1: Total PnL | N1: Avg PnL
K2: =COUNTA(Dhan_Trade_Summary!A:A)-1 -> 0 | L2: =COUNTIFS(Dhan_Trade_Summary!R:R,">0")/COUNTA(Dhan_Trade_Summary!A:A)-1 -> -1 | M2: =SUM(Dhan_Trade_Summary!R:R) -> 0 | N2: =AVERAGE(Dhan_Trade_Summary!R:R) -> #DIV/0!
K3: =COUNTA(Dhan_Trade_Summary!A:A)-1 -> 0 | L3: =COUNTIFS(Dhan_Trade_Summary!R:R,">0")/COUNTA(Dhan_Trade_Summary!A:A)-1 -> -1 | M3: =SUM(Dhan_Trade_Summary!R:R) -> 0 | N3: =AVERAGE(Dhan_Trade_Summary!R:R) -> #DIV/0!
K4: =COUNTA(Dhan_Trade_Summary!A:A)-1 -> 0 | L4: =COUNTIFS(Dhan_Trade_Summary!R:R,">0")/COUNTA(Dhan_Trade_Summary!A:A)-1 -> -1 | M4: =SUM(Dhan_Trade_Summary!R:R) -> 0 | N4: =AVERAGE(Dhan_Trade_Summary!R:R) -> #DIV/0!
K5: =COUNTA(Dhan_Trade_Summary!A:A)-1 -> 0 | L5: =COUNTIFS(Dhan_Trade_Summary!R:R,">0")/COUNTA(Dhan_Trade_Summary!A:A)-1 -> -1 | M5: =SUM(Dhan_Trade_Summary!R:R) -> 0 | N5: =AVERAGE(Dhan_Trade_Summary!R:R) -> #DIV/0!
K6: =COUNTA(Dhan_Trade_Summary!A:A)-1 -> 0 | L6: =COUNTIFS(Dhan_Trade_Summary!R:R,">0")/COUNTA(Dhan_Trade_Summary!A:A)-1 -> -1 | M6: =SUM(Dhan_Trade_Summary!R:R) -> 0 | N6: =AVERAGE(Dhan_Trade_Summary!R:R) -> #DIV/0!
K7: =COUNTA(Dhan_Trade_Summary!A:A)-1 -> 0 | L7: =COUNTIFS(Dhan_Trade_Summary!R:R,">0")/COUNTA(Dhan_Trade_Summary!A:A)-1 -> -1 | M7: =SUM(Dhan_Trade_Summary!R:R) -> 0 | N7: =AVERAGE(Dhan_Trade_Summary!R:R) -> #DIV/0!
K8: =COUNTA(Dhan_Trade_Summary!A:A)-1 -> 0 | L8: =COUNTIFS(Dhan_Trade_Summary!R:R,">0")/COUNTA(Dhan_Trade_Summary!A:A)-1 -> -1 | M8: =SUM(Dhan_Trade_Summary!R:R) -> 0 | N8: =AVERAGE(Dhan_Trade_Summary!R:R) -> #DIV/0!
K9: =COUNTA(Dhan_Trade_Summary!A:A)-1 -> 0 | L9: =COUNTIFS(Dhan_Trade_Summary!R:R,">0")/COUNTA(Dhan_Trade_Summary!A:A)-1 -> -1 | M9: =SUM(Dhan_Trade_Summary!R:R) -> 0 | N9: =AVERAGE(Dhan_Trade_Summary!R:R) -> #DIV/0!
K10: =COUNTA(Dhan_Trade_Summary!A:A)-1 -> 0 | L10: =COUNTIFS(Dhan_Trade_Summary!R:R,">0")/COUNTA(Dhan_Trade_Summary!A:A)-1 -> -1 | M10: =SUM(Dhan_Trade_Summary!R:R) -> 0 | N10: =AVERAGE(Dhan_Trade_Summary!R:R) -> #DIV/0!
K11: =COUNTA(Dhan_Trade_Summary!A:A)-1 -> 0 | L11: =COUNTIFS(Dhan_Trade_Summary!R:R,">0")/COUNTA(Dhan_Trade_Summary!A:A)-1 -> -1 | M11: =SUM(Dhan_Trade_Summary!R:R) -> 0 | N11: =AVERAGE(Dhan_Trade_Summary!R:R) -> #DIV/0!
K12: =COUNTA(Dhan_Trade_Summary!A:A)-1 -> 0 | L12: =COUNTIFS(Dhan_Trade_Summary!R:R,">0")/COUNTA(Dhan_Trade_Summary!A:A)-1 -> -1 | M12: =SUM(Dhan_Trade_Summary!R:R) -> 0 | N12: =AVERAGE(Dhan_Trade_Summary!R:R) -> #DIV/0!
K13: =COUNTA(Dhan_Trade_Summary!A:A)-1 -> 0 | L13: =COUNTIFS(Dhan_Trade_Summary!R:R,">0")/COUNTA(Dhan_Trade_Summary!A:A)-1 -> -1 | M13: =SUM(Dhan_Trade_Summary!R:R) -> 0 | N13: =AVERAGE(Dhan_Trade_Summary!R:R) -> #DIV/0!
... K343: =COUNTA(Dhan_Trade_Summary!A:A)-1 -> 0 | L343: =COUNTIFS(Dhan_Trade_Summary!R:R,">0")/COUNTA(Dhan_Trade_Summary!A:A)-1 -> -1 | M343: =SUM(Dhan_Trade_Summary!R:R) -> 0 | N343: =AVERAGE(Dhan_Trade_Summary!R:R) -> #DIV/0!

Sheet Dhan_Alert_Log
A1: Timestamp | B1: Alert Type | C1: Severity | D1: Message | E1: PnL | F1: Trading Symbol | G1: Action Taken | H1: Resolution Status
